<robot name="yumi">
  <material name="Black">
    <color rgba="0.0 0.0 0.0 1.0" />
  </material>
  <material name="Blue">
    <color rgba="0.0 0.0 0.8 1.0" />
  </material>
  <material name="Green">
    <color rgba="0.0 0.8 0.0 1.0" />
  </material>
  <material name="Grey">
    <color rgba="0.5 0.5 0.5 1.0" />
  </material>
  <material name="Light_Grey">
    <color rgba="0.8 0.8 0.8 1.0" />
  </material>
  <material name="Ivory">
    <color rgba="1.0 1.0 0.94 1.0" />
  </material>
  <material name="Orange">
    <color rgba="1.0 0.4235294117647059 0.0392156862745098 1.0" />
  </material>
  <material name="Brown">
    <color rgba="0.8705882352941177 0.8117647058823529 0.7647058823529411 1.0" />
  </material>
  <material name="Red">
    <color rgba="0.8 0.0 0.0 1.0" />
  </material>
  <material name="White">
    <color rgba="1.0 1.0 1.0 1.0" />
  </material>
  <link name="yumi_body">
    <inertial>
      <origin rpy="0 0 0" xyz="0 0 0" />
      <mass value="15" />
      <inertia ixx="0.5" ixy="0" ixz="0" iyy="0.6" iyz="0" izz="0.3" />
    </inertial>
    <visual>
      <origin rpy="0 0 0" xyz="0 0 0" />
      <geometry>
        <mesh filename="/workspace/src/yumi_description/meshes/body.stl" />
      </geometry>
      <material name="Light_Grey" />
    </visual>
    <collision>
      <origin rpy="0 0 0" xyz="0 0 0" />
      <geometry>
        <mesh filename="/workspace/src/yumi_description/meshes/coarse/body.stl" />
      </geometry>
      <material name="Light_Grey" />
    </collision>
  </link>
  <joint name="yumi_joint_1_r" type="revolute">
    <parent link="yumi_body" />
    <child link="yumi_link_1_r" />
    <origin rpy="-0.9795   -0.5682   -2.3155" xyz="0.05355 -0.0725 0.41492" />
    <axis xyz="0 0 1" />
    <limit effort="300" lower="-2.940879789610445" upper="2.940879789610445" velocity="3.141592653589793" />
    <dynamics damping="0.5" />
  </joint>
  <link name="yumi_link_1_r">
    <inertial>
      <origin rpy="0 0 0" xyz="0 -0.03 0.12" />
      <mass value="2" />
      <inertia ixx="0.1" ixy="0" ixz="0" iyy="0.1" iyz="0" izz="0.1" />
    </inertial>
    <visual>
      <origin rpy="0 0 0" xyz="0 0 0" />
      <geometry>
        <mesh filename="/workspace/src/yumi_description/meshes/link_1.stl" />
      </geometry>
      <material name="Grey" />
    </visual>
    <collision>
      <origin rpy="0 0 0" xyz="0 0 0" />
      <geometry>
        <mesh filename="/workspace/src/yumi_description/meshes/coarse/link_1.stl" />
      </geometry>
      <material name="Grey" />
    </collision>
  </link>
  <joint name="yumi_joint_2_r" type="revolute">
    <parent link="yumi_link_1_r" />
    <child link="yumi_link_2_r" />
    <origin rpy="1.5707963267948966 0.0 0.0" xyz="0.03 0.0 0.1" />
    <axis xyz="0 0 1" />
    <limit effort="300" lower="-2.504547476611863" upper="0.7592182246175333" velocity="3.141592653589793" />
    <dynamics damping="0.5" />
  </joint>
  <link name="yumi_link_2_r">
    <inertial>
      <origin rpy="0 0 0" xyz="0 0 0" />
      <mass value="2" />
      <inertia ixx="0.1" ixy="0" ixz="0" iyy="0.1" iyz="0" izz="0.1" />
    </inertial>
    <visual>
      <origin rpy="0 0 0" xyz="0 0 0" />
      <geometry>
        <mesh filename="/workspace/src/yumi_description/meshes/link_2.stl" />
      </geometry>
      <material name="Grey" />
    </visual>
    <collision>
      <origin rpy="0 0 0" xyz="0 0 0" />
      <geometry>
        <mesh filename="/workspace/src/yumi_description/meshes/coarse/link_2.stl" />
      </geometry>
      <material name="Grey" />
    </collision>
  </link>
  <joint name="yumi_joint_7_r" type="revolute">
    <parent link="yumi_link_2_r" />
    <child link="yumi_link_3_r" />
    <origin rpy="-1.5707963267948966 0.0 0.0" xyz="-0.03 0.17283 0.0" />
    <axis xyz="0 0 1" />
    <limit effort="300" lower="-2.940879789610445" upper="2.940879789610445" velocity="3.141592653589793" />
    <dynamics damping="0.5" />
  </joint>
  <link name="yumi_link_3_r">
    <inertial>
      <origin rpy="0 0 0" xyz="0 0 0" />
      <mass value="2" />
      <inertia ixx="0.1" ixy="0" ixz="0" iyy="0.1" iyz="0" izz="0.1" />
    </inertial>
    <visual>
      <origin rpy="0 0 0" xyz="0 0 0" />
      <geometry>
        <mesh filename="/workspace/src/yumi_description/meshes/link_3.stl" />
      </geometry>
      <material name="Grey" />
    </visual>
    <collision>
      <origin rpy="0 0 0" xyz="0 0 0" />
      <geometry>
        <mesh filename="/workspace/src/yumi_description/meshes/coarse/link_3.stl" />
      </geometry>
      <material name="Grey" />
    </collision>
  </link>
  <joint name="yumi_joint_3_r" type="revolute">
    <parent link="yumi_link_3_r" />
    <child link="yumi_link_4_r" />
    <origin rpy="1.5707963267948966 -1.5707963267948966 0.0" xyz="-0.04188 0.0 0.07873" />
    <axis xyz="0 0 1" />
    <limit effort="300" lower="-2.155481626212997" upper="1.3962634015954636" velocity="3.141592653589793" />
    <dynamics damping="0.5" />
  </joint>
  <link name="yumi_link_4_r">
    <inertial>
      <origin rpy="0 0 0" xyz="0 0 0" />
      <mass value="2" />
      <inertia ixx="0.1" ixy="0" ixz="0" iyy="0.1" iyz="0" izz="0.1" />
    </inertial>
    <visual>
      <origin rpy="0 0 0" xyz="0 0 0" />
      <geometry>
        <mesh filename="/workspace/src/yumi_description/meshes/link_4.stl" />
      </geometry>
      <material name="Grey" />
    </visual>
    <collision>
      <origin rpy="0 0 0" xyz="0 0 0" />
      <geometry>
        <mesh filename="/workspace/src/yumi_description/meshes/coarse/link_4.stl" />
      </geometry>
      <material name="Grey" />
    </collision>
  </link>
  <joint name="yumi_joint_4_r" type="revolute">
    <parent link="yumi_link_4_r" />
    <child link="yumi_link_5_r" />
    <origin rpy="-1.5707963267948966 0.0 0.0" xyz="0.0405 0.16461 0.0" />
    <axis xyz="0 0 1" />
    <limit effort="300" lower="-5.061454830783555" upper="5.061454830783555" velocity="6.981317007977318" />
    <dynamics damping="0.5" />
  </joint>
  <link name="yumi_link_5_r">
    <inertial>
      <origin rpy="0 0 0" xyz="0 0 0" />
      <mass value="2" />
      <inertia ixx="0.1" ixy="0" ixz="0" iyy="0.1" iyz="0" izz="0.1" />
    </inertial>
    <visual>
      <origin rpy="0 0 0" xyz="0 0 0" />
      <geometry>
        <mesh filename="/workspace/src/yumi_description/meshes/link_5.stl" />
      </geometry>
      <material name="Grey" />
    </visual>
    <collision>
      <origin rpy="0 0 0" xyz="0 0 0" />
      <geometry>
        <mesh filename="/workspace/src/yumi_description/meshes/coarse/link_5.stl" />
      </geometry>
      <material name="Grey" />
    </collision>
  </link>
  <joint name="yumi_joint_5_r" type="revolute">
    <parent link="yumi_link_5_r" />
    <child link="yumi_link_6_r" />
    <origin rpy="1.5707963267948966 0.0 0.0" xyz="-0.027 0 0.10039" />
    <axis xyz="0 0 1" />
    <limit effort="300" lower="-1.53588974175501" upper="2.4085543677521746" velocity="6.981317007977318" />
    <dynamics damping="0.5" />
  </joint>
  <link name="yumi_link_6_r">
    <inertial>
      <origin rpy="0 0 0" xyz="0 0 0" />
      <mass value="2" />
      <inertia ixx="0.1" ixy="0" ixz="0" iyy="0.1" iyz="0" izz="0.1" />
    </inertial>
    <visual>
      <origin rpy="0 0 0" xyz="0 0 0" />
      <geometry>
        <mesh filename="/workspace/src/yumi_description/meshes/link_6.stl" />
      </geometry>
      <material name="Grey" />
    </visual>
    <collision>
      <origin rpy="0 0 0" xyz="0 0 0" />
      <geometry>
        <mesh filename="/workspace/src/yumi_description/meshes/coarse/link_6.stl" />
      </geometry>
      <material name="Grey" />
    </collision>
  </link>
  <joint name="yumi_joint_6_r" type="revolute">
    <parent link="yumi_link_6_r" />
    <child link="yumi_link_7_r" />
    <origin rpy="-1.5707963267948966 0.0 0.0" xyz="0.027 0.029 0.0" />
    <axis xyz="0 0 1" />
    <limit effort="300" lower="-3.9968039870670142" upper="3.9968039870670142" velocity="6.981317007977318" />
    <dynamics damping="0.5" />
  </joint>
  <link name="yumi_link_7_r">
    <inertial>
      <origin rpy="0 0 0" xyz="0 0 0" />
      <mass value="2" />
      <inertia ixx="0.1" ixy="0" ixz="0" iyy="0.1" iyz="0" izz="0.1" />
    </inertial>
    <visual>
      <origin rpy="0 0 0" xyz="0 0 0" />
      <geometry>
        <mesh filename="/workspace/src/yumi_description/meshes/link_7.stl" />
      </geometry>
      <material name="Grey" />
    </visual>
    <collision>
      <origin rpy="0 0 0" xyz="0 0 0" />
      <geometry>
        <mesh filename="/workspace/src/yumi_description/meshes/coarse/link_7.stl" />
      </geometry>
      <material name="Grey" />
    </collision>
  </link>
  <joint name="yumi_link_7_r_joint" type="fixed">
    <origin rpy="0 0 3.141592653589793" xyz="0 0 0.007" />
    <parent link="yumi_link_7_r" />
    <child link="gripper_r_base" />
  </joint>
  <link name="gripper_r_base">
    <inertial>
      <origin rpy="0 0 0" xyz="0 0 0" />
      <mass value="0.2" />
      <inertia ixx="0.0001" ixy="0" ixz="0" iyy="0.0001" iyz="0" izz="0.0001" />
    </inertial>
    <visual>
      <origin rpy="0 0 0" xyz="0 0 0" />
      <geometry>
        <mesh filename="/workspace/src/yumi_description/meshes/gripper/base.stl" />
      </geometry>
      <material name="Light_Grey" />
    </visual>
    <collision>
      <origin rpy="0 0 0" xyz="0 0 0" />
      <geometry>
        <mesh filename="/workspace/src/yumi_description/meshes/gripper/coarse/base.stl" />
      </geometry>
      <material name="Light_Grey" />
    </collision>
  </link>
  <joint name="gripper_r_base_to_grasp_frame" type="fixed">
    <parent link="gripper_r_base" />
    <child link="gripper_r_grasp_frame" />
    <origin rpy="0 0 0" xyz="0 0 0.11" />
  </joint>
  <link name="gripper_r_grasp_frame" />
  <joint name="gripper_r_joint" type="prismatic">
    <parent link="gripper_r_base" />
    <child link="gripper_r_finger_r" />
    <origin rpy="0 0 0" xyz="0 -0.0065 0.0837" />
    <axis xyz="-1 0 0" />
    <limit effort="20" lower="0" upper="0.025" velocity="2" />
    <dynamics damping="1.0" />
  </joint>
  <link name="gripper_r_finger_r">
    <inertial>
      <origin rpy="0 0 0" xyz="0 0 0" />
      <mass value="0.01" />
      <inertia ixx="0.000001" ixy="0" ixz="0" iyy="0.000001" iyz="0" izz="0.000001" />
    </inertial>
    <visual>
      <origin rpy="0 0 0" xyz="0 0 0" />
      <geometry>
        <mesh filename="/workspace/src/yumi_description/meshes/gripper/finger.stl" />
      </geometry>
      <material name="Blue" />
    </visual>
    <collision>
      <origin rpy="0 0 0" xyz="0 0 0" />
      <geometry>
        <mesh filename="/workspace/src/yumi_description/meshes/gripper/coarse/finger.stl" />
      </geometry>
      <material name="Blue" />
    </collision>
  </link>
  <joint name="gripper_r_joint_m" type="prismatic">
    <parent link="gripper_r_base" />
    <child link="gripper_r_finger_l" />
    <origin rpy="0 0 3.141592653589793" xyz="0 0.0065 0.0837" />
    <axis xyz="-1 0 0" />
    <limit effort="20" lower="0" upper="0.025" velocity="2" />
    <dynamics damping="1.0" />
    <mimic joint="gripper_r_joint" />
  </joint>
  <link name="gripper_r_finger_l">
    <inertial>
      <origin rpy="0 0 0" xyz="0 0 0" />
      <mass value="0.01" />
      <inertia ixx="0.000001" ixy="0" ixz="0" iyy="0.000001" iyz="0" izz="0.000001" />
    </inertial>
    <visual>
      <origin rpy="0 0 0" xyz="0 0 0" />
      <geometry>
        <mesh filename="/workspace/src/yumi_description/meshes/gripper/finger.stl" />
      </geometry>
      <material name="Blue" />
    </visual>
    <collision>
      <origin rpy="0 0 0" xyz="0 0 0" />
      <geometry>
        <mesh filename="/workspace/src/yumi_description/meshes/gripper/coarse/finger.stl" />
      </geometry>
      <material name="Blue" />
    </collision>
  </link>
</robot>